\documentclass[../../LearnCpp.tex]{subfiles}

\begin{document}

\asubsection{6}{Rethrowing exceptions}

有时候用户可能会遇到捕获了一个异常，但是并不想（或没有能力）完全的在该时间点进行异常处理。
这常见于当用户希望输出错误日志时，还需传递异常给真正的处理者。

试想如下场景：

\begin{lstlisting}[language=C++]
Database* createDatabase(std::string filename)
{
    try
    {
        Database* d = new Database(filename);
        d->open(); // 假设这里抛出了一个 int 异常
        return d;
    }
    catch (int exception)
    {
        // 数据库创建失败
        delete d;
        // 将错误写入日志
        g_log.logError("Creation of Database failed");
    }

    return nullptr;
}
\end{lstlisting}

考虑下面的函数：

\begin{lstlisting}[language=C++]
int getIntValueFromDatabase(Database* d, std::string table, std::string key)
{
    assert(d);

    try
    {
        return d->getIntValue(table, key); // 失败时抛出 int 异常
    }
    catch (int exception)
    {
        // 将错误写入日志
        g_log.logError("getIntValueFromDatabase failed");

        // 然而并没有实际处理这个错误，这里应该怎么做？
    }
}
\end{lstlisting}

\subsubsection*{抛出一个新的异常}

一个显而易见的方案就是抛出一个新的异常。

\begin{lstlisting}[language=C++]
int getIntValueFromDatabase(Database* d, std::string table, std::string key)
{
    assert(d);

    try
    {
        return d->getIntValue(table, key); // 失败时抛出 int 异常
    }
    catch (int exception)
    {
        // 将错误写入日志
        g_log.logError("getIntValueFromDatabase failed");

        throw 'q'; // 抛出字符异常 'q' 给栈，给 getIntValueFromDatabase() 的调用者去处理
    }
}
\end{lstlisting}

\subsubsection*{重新抛出一个异常（错误方式）}

\begin{lstlisting}[language=C++]
int getIntValueFromDatabase(Database* d, std::string table, std::string key)
{
    assert(d);

    try
    {
        return d->getIntValue(table, key); // 失败时抛出 int 异常
    }
    catch (int exception)
    {
        // 将错误写入日志
        g_log.logError("getIntValueFromDatabase failed");

        throw exception;
    }
}
\end{lstlisting}

尽管这可以工作，这个方法存在一些缺陷。
首先，并不会抛出与捕获到的异常完全相同 -- 而是抛出拷贝初始化的异常变量的副本。
尽管编译器可以免除拷贝，但是也有可能不免除，从而导致性能下降。

但是最重要的是考虑下面的例子：

\begin{lstlisting}[language=C++]
int getIntValueFromDatabase(Database* d, std::string table, std::string key)
{
    assert(d);

    try
    {
        return d->getIntValue(table, key); // 失败时抛出 int 异常
    }
    catch (Base &exception)
    {
        // 将错误写入日志
        g_log.logError("getIntValueFromDatabase failed");

        throw exception; // 危险：抛出一个 Base 对象，而不是 Derived 对象
    }
}
\end{lstlisting}

\subsubsection*{重新抛出一个异常（正确方式）}

幸运的是 C++ 提供一种重新抛出完全一致异常的方法。
仅需要使用 throw 关键字在 catch block 中（且不带关联变量），像是这样：

\begin{lstlisting}[language=C++]
#include <iostream>
class Base
{
public:
    Base() {}
    virtual void print() { std::cout << "Base"; }
};

class Derived: public Base
{
public:
    Derived() {}
    void print() override { std::cout << "Derived"; }
};

int main()
{
    try
    {
        try
        {
            throw Derived{};
        }
        catch (Base& b)
        {
            std::cout << "Caught Base b, which is actually a ";
            b.print();
            std::cout << '\n';
            throw; // 注意：这里重新抛出异常对象
        }
    }
    catch (Base& b)
    {
        std::cout << "Caught Base b, which is actually a ";
        b.print();
        std::cout << '\n';
    }

    return 0;
}
\end{lstlisting}

规则：当需要抛出同样的异常时，单个使用 throw 关键字。

\end{document}
